2021-06-20 05:13:47,095 INFO    Thread-7441:2727604 [wandb_setup.py:_flush():69] setting env: {'entity': 'naddeok', 'project': 'ECG Heartbeat Verifier', 'root_dir': '/home/naddeok5/HeartBreaker', 'run_id': 'u16rpsxe', 'sweep_param_path': '/home/naddeok5/HeartBreaker/wandb/sweep-gq8mwnhp/config-u16rpsxe.yaml', 'sweep_id': 'gq8mwnhp'}
2021-06-20 05:13:47,095 INFO    Thread-7441:2727604 [wandb_setup.py:_flush():69] setting login settings: {}
2021-06-20 05:13:47,095 INFO    Thread-7441:2727604 [wandb_init.py:_log_setup():336] Logging user logs to /home/naddeok5/HeartBreaker/wandb/run-20210620_051347-u16rpsxe/logs/debug.log
2021-06-20 05:13:47,095 INFO    Thread-7441:2727604 [wandb_init.py:_log_setup():337] Logging internal logs to /home/naddeok5/HeartBreaker/wandb/run-20210620_051347-u16rpsxe/logs/debug-internal.log
2021-06-20 05:13:47,096 INFO    Thread-7441:2727604 [wandb_init.py:init():369] calling init triggers
2021-06-20 05:13:47,096 INFO    Thread-7441:2727604 [wandb_init.py:init():374] wandb.init called with sweep_config: {'batch_size': 60, 'criterion': 'binary_cross_entropy', 'epochs': 655, 'learning_rate': 0.0921806678962685, 'momentum': 0.9, 'optimizer': 'adam', 'scheduler': None, 'use_SAM': False, 'weight_decay': 1e-05}
config: {'epochs': 20, 'batch_size': 1, 'momentum': 0.9, 'weight_decay': 1e-05, 'learning_rate': 1e-05, 'optimizer': 'adam', 'scheduler': 'Cosine Annealing', 'criterion': 'binary_cross_entropy', 'use_SAM': True}
2021-06-20 05:13:47,096 INFO    Thread-7441:2727604 [wandb_init.py:init():418] starting backend
2021-06-20 05:13:47,096 INFO    Thread-7441:2727604 [backend.py:_multiprocessing_setup():70] multiprocessing start_methods=fork,spawn,forkserver, using: spawn
2021-06-20 05:13:47,100 INFO    Thread-7441:2727604 [backend.py:ensure_launched():132] starting backend process...
2021-06-20 05:13:47,144 INFO    Thread-7441:2727604 [backend.py:ensure_launched():136] started backend process with pid: 747212
2021-06-20 05:13:47,146 INFO    Thread-7441:2727604 [wandb_init.py:init():423] backend started and connected
2021-06-20 05:13:47,147 INFO    Thread-7441:2727604 [wandb_run.py:_config_callback():787] config_cb None None {'batch_size': 60, 'criterion': 'binary_cross_entropy', 'epochs': 655, 'learning_rate': 0.0921806678962685, 'momentum': 0.9, 'optimizer': 'adam', 'scheduler': None, 'use_SAM': False, 'weight_decay': 1e-05}
2021-06-20 05:13:47,148 INFO    Thread-7441:2727604 [wandb_init.py:init():465] updated telemetry
2021-06-20 05:13:47,149 INFO    Thread-7441:2727604 [wandb_init.py:init():484] communicating current version
2021-06-20 05:13:48,275 INFO    Thread-7441:2727604 [wandb_init.py:init():489] got version response upgrade_message: "wandb version 0.10.32 is available!  To upgrade, please run:\n $ pip install wandb --upgrade"

2021-06-20 05:13:48,275 INFO    Thread-7441:2727604 [wandb_init.py:init():497] communicating run to backend with 30 second timeout
2021-06-20 05:13:48,392 INFO    Thread-7441:2727604 [wandb_init.py:init():522] starting run threads in backend
2021-06-20 05:13:49,812 INFO    Thread-7441:2727604 [wandb_run.py:_console_start():1565] atexit reg
2021-06-20 05:13:49,813 INFO    Thread-7441:2727604 [wandb_run.py:_redirect():1412] redirect: SettingsConsole.REDIRECT
2021-06-20 05:13:49,813 INFO    Thread-7441:2727604 [wandb_run.py:_redirect():1417] Redirecting console.
2021-06-20 05:13:49,813 ERROR   Thread-7441:2727604 [wandb_run.py:_redirect():1482] Failed to redirect.
Traceback (most recent call last):
  File "/home/naddeok5/.local/lib/python3.8/site-packages/wandb/sdk/wandb_run.py", line 1475, in _redirect
    out_redir.install()
  File "/home/naddeok5/.local/lib/python3.8/site-packages/wandb/sdk/lib/redirect.py", line 605, in install
    _WSCH.add_fd(self._pipe_read_fd)
  File "/home/naddeok5/.local/lib/python3.8/site-packages/wandb/sdk/lib/redirect.py", line 555, in add_fd
    self._register()
  File "/home/naddeok5/.local/lib/python3.8/site-packages/wandb/sdk/lib/redirect.py", line 540, in _register
    old_handler = signal.signal(signal.SIGWINCH, lambda *_: None)
  File "/usr/lib/python3.8/signal.py", line 47, in signal
    handler = _signal.signal(_enum_to_int(signalnum), _enum_to_int(handler))
ValueError: signal only works in main thread
2021-06-20 05:13:49,814 INFO    Thread-7441:2727604 [wandb_init.py:init():546] run started, returning control to user process
2021-06-20 05:44:34,604 ERROR   Thread-1  :2727604 [internal_api.py:execute():130] 500 response executing GraphQL.
2021-06-20 05:44:34,605 ERROR   Thread-1  :2727604 [internal_api.py:execute():131] {"errors":[{"message":"Error 1040: Too many connections","path":["agentHeartbeat"]}],"data":{"agentHeartbeat":null}}
2021-06-20 05:44:35,730 ERROR   Thread-1  :2727604 [internal_api.py:execute():130] 500 response executing GraphQL.
2021-06-20 05:44:35,731 ERROR   Thread-1  :2727604 [internal_api.py:execute():131] {"error":"Error 1040: Too many connections"}

2021-06-20 05:44:38,094 ERROR   Thread-1  :2727604 [internal_api.py:execute():130] 500 response executing GraphQL.
2021-06-20 05:44:38,095 ERROR   Thread-1  :2727604 [internal_api.py:execute():131] {"error":"Error 1040: Too many connections"}

2021-06-20 05:44:38,095 ERROR   Thread-1  :2727604 [retry.py:__call__():126] Retry attempt failed:
Traceback (most recent call last):
  File "/home/naddeok5/.local/lib/python3.8/site-packages/wandb/sdk/lib/retry.py", line 102, in __call__
    result = self._call_fn(*args, **kwargs)
  File "/home/naddeok5/.local/lib/python3.8/site-packages/wandb/sdk/internal/internal_api.py", line 133, in execute
    six.reraise(*sys.exc_info())
  File "/usr/lib/python3/dist-packages/six.py", line 703, in reraise
    raise value
  File "/home/naddeok5/.local/lib/python3.8/site-packages/wandb/sdk/internal/internal_api.py", line 127, in execute
    return self.client.execute(*args, **kwargs)
  File "/home/naddeok5/.local/lib/python3.8/site-packages/wandb/vendor/gql-0.2.0/gql/client.py", line 52, in execute
    result = self._get_result(document, *args, **kwargs)
  File "/home/naddeok5/.local/lib/python3.8/site-packages/wandb/vendor/gql-0.2.0/gql/client.py", line 60, in _get_result
    return self.transport.execute(document, *args, **kwargs)
  File "/home/naddeok5/.local/lib/python3.8/site-packages/wandb/vendor/gql-0.2.0/gql/transport/requests.py", line 39, in execute
    request.raise_for_status()
  File "/usr/lib/python3/dist-packages/requests/models.py", line 940, in raise_for_status
    raise HTTPError(http_error_msg, response=self)
requests.exceptions.HTTPError: 500 Server Error: Internal Server Error for url: https://api.wandb.ai/graphql
2021-06-20 05:44:43,001 ERROR   Thread-1  :2727604 [internal_api.py:execute():130] 500 response executing GraphQL.
2021-06-20 05:44:43,002 ERROR   Thread-1  :2727604 [internal_api.py:execute():131] {"error":"Error 1040: Too many connections"}

